<?xml version='1.0'?>
<sdf version='1.6'>
  <model name='iris'>
    <link name='base_link'>
      <inertial>
        <mass>58.65</mass> <!-- Cheio é 77.80kg | vazio é 58.65 -->
        <inertia>
          <ixx>18.58</ixx>
          <ixy>0</ixy>
          <ixz>0</ixz>
          <iyy>19.4</iyy>
          <iyz>0</iyz>
          <izz>27.27</izz>
        </inertia>
        <pose>0 0 0.75215 0 0 0</pose>	<!-- CG vazio é 0.75215 -->
      </inertial>
      <pose>0 0 0 0 0 -1.5708</pose>
      <gravity>1</gravity>
      <self_collide>0</self_collide>
      <kinematic>0</kinematic>
      <enable_wind>1</enable_wind>
      <visual name='visual'>
        <pose>-0.015 0.01 0 0 0 0</pose>
        <geometry>
          <mesh>
            <uri>model://Partes/frame_3.dae</uri>
            <scale>1 1 1</scale>
          </mesh>
        </geometry>
        <material>
          <lighting>1</lighting>
          <script>
            <uri>file://media/materials/scripts/gazebo.material</uri>
            <name>Gazebo/Black</name>
          </script>
			<shader type="pixel" name="gazebo.material">
			  <normal_map>file://media/materials/textures/carbon_fiber_normal.png</normal_map>
			</shader>
          <ambient>0.3 0.3 0.3 1</ambient>
          <diffuse>0.7 0.7 0.7 1</diffuse>
          <specular>0.01 0.01 0.01 1</specular>
          <emissive>0 0 0 1</emissive>
        </material>
        <transparency>0</transparency>
        <cast_shadows>1</cast_shadows>
      </visual>
      <collision name='base_link_collision'>
        <pose>0 0 0.5 0 0 0</pose>
        <geometry>
          <box>
            <size>0.4826 0.4826 1.00</size>
          </box>
        </geometry>
        <surface>
          <contact>
            <ode>
              <max_vel>100.0</max_vel>
              <min_depth>0.001</min_depth>
            </ode>
          </contact>
          <friction>
            <ode>
              <mu>100000.0</mu>
              <mu2>100000.0</mu2>
            </ode>
          </friction>
        </surface>
      </collision>
    </link>

	<link name='bateria'>
	  <pose>0 0 0.8 0 0 0</pose>
	  <inertial>
		<pose>0 0 0 0 0 0</pose>
		<mass>0.01</mass>
		<inertia>
		  <ixx>0.02</ixx>
		  <ixy>0</ixy>
		  <ixz>0</ixz>
		  <iyy>0.02</iyy>
		  <iyz>0</iyz>
		  <izz>0.02</izz>
		</inertia>
	  </inertial>
	  <visual name="bateria_visual">
		<pose>0 0 0 0 0 0</pose>
		<geometry>
		  <box>
			<size>0.42 0.25 0.08</size>
		  </box>
		</geometry>
		<material>
		  <script>
			<uri>file://media/materials/scripts/gazebo.material</uri>
			<name>Gazebo/Green</name>
		  </script>
		</material>
	  </visual>
	</link>
    <joint name='bateria/joint' type='revolute'>
      <child>bateria</child>
      <parent>base_link</parent>
      <axis>
        <xyz>0 0 1</xyz>
        <limit>
          <lower>0</lower>
          <upper>0</upper>
          <effort>0</effort>
          <velocity>0</velocity>
        </limit>
        <dynamics>
          <damping>1.0</damping>
        </dynamics>
        <use_parent_model_frame>1</use_parent_model_frame>
      </axis>
      <physics>
        <ode>
          <implicit_spring_damper>1</implicit_spring_damper>
        </ode>
      </physics>
    </joint>

	
	<link name='iris/imu_link'>
	  <pose>0.0 0.0 0.75215 0 0 0</pose>
	  <inertial>
		<pose>0 0 0 0 0 0</pose>
		<mass>0.015</mass>
		<inertia>
		  <ixx>0.00001</ixx>
		  <ixy>0</ixy>
		  <ixz>0</ixz>
		  <iyy>0.00002</iyy>
		  <iyz>0</iyz>
		  <izz>0.00002</izz>
		</inertia>
	  </inertial>
	  <visual name="imu_visual">
		<pose>0 0 0 3.141593 0 0</pose>
		<geometry>
		  <box>
			<size>0.1 0.05 0.04</size>
		  </box>
		</geometry>
		<material>
		  <script>
			<uri>file://media/materials/scripts/gazebo.material</uri>
			<name>Gazebo/Red</name>
		  </script>
		</material>
	  </visual>
	  <sensor name="imu_sensor" type="imu">
		<pose>0 0 0 3.141593 0 0</pose>
		<always_on>1</always_on>
		<update_rate>1000.0</update_rate>
	  </sensor>
	</link>

    <link name='rotor_0'>
      <inertial>
        <mass>0.2</mass>
        <inertia>
          <ixx>0.0194</ixx>
          <ixy>0</ixy>
          <ixz>0</ixz>
          <iyy>0.0194</iyy>
          <iyz>0</iyz>
          <izz>0.0097</izz>
        </inertia>
        <pose>0 0 0 0 -0 0</pose>
      </inertial>
      <pose>1.125441 -0.468821 1.08 -0.139626 -0.087266 -0.398302</pose>
      <gravity>1</gravity>
      <self_collide>0</self_collide>
      <kinematic>0</kinematic>
      <enable_wind>1</enable_wind>
      <visual name='visual'>
        <pose>0 0 0 0 0 0</pose>
        <geometry>
          <mesh>
            <uri>model://Partes/helices_CCW_T30.dae</uri>
            <scale>1 1 1</scale>
          </mesh>
        </geometry>
        <material>
          <lighting>1</lighting>
          <script>
            <uri>file://media/materials/scripts/gazebo.material</uri>
            <name>Gazebo/Grey</name>
          </script>
          <shader type='pixel'>
            <normal_map>__default__</normal_map>
          </shader>
          <ambient>0.3 0.3 0.3 1</ambient>
          <diffuse>0.7 0.7 0.7 1</diffuse>
          <specular>0.01 0.01 0.01 1</specular>
          <emissive>0 0 0 1</emissive>
        </material>
        <transparency>0</transparency>
        <cast_shadows>1</cast_shadows>
      </visual>
      <collision name='rotor_0_collision'>
        <pose>0 0 0 0 -0 0</pose>
        <geometry>
          <cylinder>
            <length>0.015</length>
            <radius>0.4826</radius>
          </cylinder>
        </geometry>
        <surface>
          <contact>
            <ode/>
          </contact>
          <friction>
            <ode/>
          </friction>
        </surface>
      </collision>
    </link>

    <link name='rotor_1'>
      <inertial>
        <mass>0.2</mass>
        <inertia>
          <ixx>0.0194</ixx>
          <ixy>0</ixy>
          <ixz>0</ixz>
          <iyy>0.0194</iyy>
          <iyz>0</iyz>
          <izz>0.0097</izz>
        </inertia>
        <pose>0 0 0 0 -0 0</pose>
      </inertial>
	  <pose>0.468821 -1.125441 1.08 0.139626 -0.087266 -1.1779</pose>
      <gravity>1</gravity>
      <self_collide>0</self_collide>
      <kinematic>0</kinematic>
      <enable_wind>1</enable_wind>
      <visual name='visual'>
        <pose>0 0 0 0 -0 0</pose>
        <geometry>
          <mesh>
            <uri>model://Partes/helices_CCW_T30.dae</uri>
            <scale>1 1 1</scale>
          </mesh>
        </geometry>
        <material>
          <lighting>1</lighting>
          <script>
            <uri>file://media/materials/scripts/gazebo.material</uri>
            <name>Gazebo/Grey</name>
          </script>
          <shader type='pixel'>
            <normal_map>__default__</normal_map>
          </shader>
          <ambient>0.3 0.3 0.3 1</ambient>
          <diffuse>0.7 0.7 0.7 1</diffuse>
          <specular>0.01 0.01 0.01 1</specular>
          <emissive>0 0 0 1</emissive>
        </material>
        <transparency>0</transparency>
        <cast_shadows>1</cast_shadows>
      </visual>
      <collision name='rotor_1_collision'>
        <pose>0 0 0 0 -0 0</pose>
        <geometry>
          <cylinder>
            <length>0.015</length>
            <radius>0.4826</radius>
          </cylinder>
        </geometry>
        <surface>
          <contact>
            <ode/>
          </contact>
          <friction>
            <ode/>
          </friction>
        </surface>
      </collision>
    </link>

    <link name='rotor_2'>
      <collision name='rotor_2_collision'>
        <pose>0 0 0 0 -0 0</pose>
        <geometry>
          <cylinder>
            <length>0.015</length>
            <radius>0.4826</radius>
          </cylinder>
        </geometry>
        <surface>
          <contact>
            <ode/>
          </contact>
          <friction>
            <ode/>
          </friction>
        </surface>
      </collision>
      <inertial>
        <mass>0.2</mass>
        <inertia>
          <ixx>0.0194</ixx>
          <ixy>0</ixy>
          <ixz>0</ixz>
          <iyy>0.0194</iyy>
          <iyz>0</iyz>
          <izz>0.0097</izz>
        </inertia>
        <pose>0 0 0 0 -0 0</pose>
      </inertial>
      <pose>-0.468821 -1.125441 1.08 -0.139626 -0.087266 -1.95531</pose>
      <gravity>1</gravity>
      <self_collide>0</self_collide>
      <kinematic>0</kinematic>
      <enable_wind>1</enable_wind>
      <visual name='visual'>
        <pose>0 0 0 0 -0 0</pose>
        <geometry>
          <mesh>
            <uri>model://Partes/helices_CCW_T30.dae</uri>
            <scale>1 1 1</scale>
          </mesh>
        </geometry>
        <material>
          <lighting>1</lighting>
          <script>
            <uri>file://media/materials/scripts/gazebo.material</uri>
            <name>Gazebo/Grey</name>
          </script>
          <shader type='pixel'>
            <normal_map>__default__</normal_map>
          </shader>
          <ambient>0.3 0.3 0.3 1</ambient>
          <diffuse>0.7 0.7 0.7 1</diffuse>
          <specular>0.01 0.01 0.01 1</specular>
          <emissive>0 0 0 1</emissive>
        </material>
        <transparency>0</transparency>
        <cast_shadows>1</cast_shadows>
      </visual>
    </link>
	
    <link name='rotor_3'>
      <collision name='rotor_3_collision'>
        <pose>0 0 0 0 -0 0</pose>
        <geometry>
          <cylinder>
            <length>0.015</length>
            <radius>0.4826</radius>
          </cylinder>
        </geometry>
        <surface>
          <contact>
            <ode/>
          </contact>
          <friction>
            <ode/>
          </friction>
        </surface>
      </collision>
      <inertial>
        <mass>0.2</mass>
        <inertia>
          <ixx>0.0194</ixx>
          <ixy>0</ixy>
          <ixz>0</ixz>
          <iyy>0.0194</iyy>
          <iyz>0</iyz>
          <izz>0.0097</izz>
        </inertia>
        <pose>0 0 0 0 -0 0</pose>
      </inertial>
      <pose>-1.125441 -0.468821 1.08 0.139626 -0.087266 -2.76134</pose>
      <gravity>1</gravity>
      <self_collide>0</self_collide>
      <kinematic>0</kinematic>
      <enable_wind>1</enable_wind>
      <visual name='visual'>
        <pose>0 0 0 0 -0 0</pose>
        <geometry>
          <mesh>
            <uri>model://Partes/helices_CCW_T30.dae</uri>
            <scale>1 1 1</scale>
          </mesh>
        </geometry>
        <material>
          <lighting>1</lighting>
          <script>
            <uri>file://media/materials/scripts/gazebo.material</uri>
            <name>Gazebo/Grey</name>
          </script>
          <shader type='pixel'>
            <normal_map>__default__</normal_map>
          </shader>
          <ambient>0.3 0.3 0.3 1</ambient>
          <diffuse>0.7 0.7 0.7 1</diffuse>
          <specular>0.01 0.01 0.01 1</specular>
          <emissive>0 0 0 1</emissive>
        </material>
        <transparency>0</transparency>
        <cast_shadows>1</cast_shadows>
      </visual>
    </link>

    <link name='rotor_4'>
      <collision name='rotor_4_collision'>
        <pose>0 0 0 0 -0 0</pose>
        <geometry>
          <cylinder>
            <length>0.015</length>
            <radius>0.4826</radius>
          </cylinder>
        </geometry>
        <surface>
          <contact>
            <ode/>
          </contact>
          <friction>
            <ode/>
          </friction>
        </surface>
      </collision>
      <inertial>
        <mass>0.2</mass>
        <inertia>
          <ixx>0.0194</ixx>
          <ixy>0</ixy>
          <ixz>0</ixz>
          <iyy>0.0194</iyy>
          <iyz>0</iyz>
          <izz>0.0097</izz>
        </inertia>
        <pose>0 0 0 0 -0 0</pose>
      </inertial>
      <pose>-1.125441 0.468821 1.08 -0.139626 -0.087266 2.76134</pose>
      <gravity>1</gravity>
      <self_collide>0</self_collide>
      <kinematic>0</kinematic>
      <enable_wind>1</enable_wind>
      <visual name='visual'>
        <pose>0 0 0 0 -0 0</pose>
        <geometry>
          <mesh>
            <uri>model://Partes/helices_CCW_T30.dae</uri>
            <scale>1 1 1</scale>
          </mesh>
        </geometry>
        <material>
          <lighting>1</lighting>
          <script>
            <uri>file://media/materials/scripts/gazebo.material</uri>
            <name>Gazebo/Grey</name>
          </script>
          <shader type='pixel'>
            <normal_map>__default__</normal_map>
          </shader>
          <ambient>0.3 0.3 0.3 1</ambient>
          <diffuse>0.7 0.7 0.7 1</diffuse>
          <specular>0.01 0.01 0.01 1</specular>
          <emissive>0 0 0 1</emissive>
        </material>
        <transparency>0</transparency>
        <cast_shadows>1</cast_shadows>
      </visual>
    </link>
	
    <link name='rotor_5'>
      <collision name='rotor_5_collision'>
        <pose>0 0 0 0 -0 0</pose>
        <geometry>
          <cylinder>
            <length>0.015</length>
            <radius>0.4826</radius>
          </cylinder>
        </geometry>
        <surface>
          <contact>
            <ode/>
          </contact>
          <friction>
            <ode/>
          </friction>
        </surface>
      </collision>
      <inertial>
        <mass>0.2</mass>
        <inertia>
          <ixx>0.0194</ixx>
          <ixy>0</ixy>
          <ixz>0</ixz>
          <iyy>0.0194</iyy>
          <iyz>0</iyz>
          <izz>0.0097</izz>
        </inertia>
        <pose>0 0 0 0 -0 0</pose>
      </inertial>
      <pose>-0.468821 1.125441 1.08 0.139626 -0.087266 1.95531</pose>
      <gravity>1</gravity>
      <self_collide>0</self_collide>
      <kinematic>0</kinematic>
      <enable_wind>1</enable_wind>
      <visual name='visual'>
        <pose>0 0 0 0 -0 0</pose>
        <geometry>
          <mesh>
            <uri>model://Partes/helices_CCW_T30.dae</uri>
            <scale>1 1 1</scale>
          </mesh>
        </geometry>
        <material>
          <lighting>1</lighting>
          <script>
            <uri>file://media/materials/scripts/gazebo.material</uri>
            <name>Gazebo/Grey</name>
          </script>
          <shader type='pixel'>
            <normal_map>__default__</normal_map>
          </shader>
          <ambient>0.3 0.3 0.3 1</ambient>
          <diffuse>0.7 0.7 0.7 1</diffuse>
          <specular>0.01 0.01 0.01 1</specular>
          <emissive>0 0 0 1</emissive>
        </material>
        <transparency>0</transparency>
        <cast_shadows>1</cast_shadows>
      </visual>
    </link>

    <link name='rotor_6'>
      <collision name='rotor_6_collision'>
        <pose>0 0 0 0 -0 0</pose>
        <geometry>
          <cylinder>
            <length>0.015</length>
            <radius>0.4826</radius>
          </cylinder>
        </geometry>
        <surface>
          <contact>
            <ode/>
          </contact>
          <friction>
            <ode/>
          </friction>
        </surface>
      </collision>
      <inertial>
        <mass>0.2</mass>
        <inertia>
          <ixx>0.0194</ixx>
          <ixy>0</ixy>
          <ixz>0</ixz>
          <iyy>0.0194</iyy>
          <iyz>0</iyz>
          <izz>0.0097</izz>
        </inertia>
        <pose>0 0 0 0 -0 0</pose>
      </inertial>
      <pose>0.468821 1.125441 1.08 -0.139626 -0.087266 1.1779</pose>
      <gravity>1</gravity>
      <self_collide>0</self_collide>
      <kinematic>0</kinematic>
      <enable_wind>1</enable_wind>
      <visual name='visual'>
        <pose>0 0 0 0 -0 0</pose>
        <geometry>
          <mesh>
            <uri>model://Partes/helices_CCW_T30.dae</uri>
            <scale>1 1 1</scale>
          </mesh>
        </geometry>
        <material>
          <lighting>1</lighting>
          <script>
            <uri>file://media/materials/scripts/gazebo.material</uri>
            <name>Gazebo/Grey</name>
          </script>
          <shader type='pixel'>
            <normal_map>__default__</normal_map>
          </shader>
          <ambient>0.3 0.3 0.3 1</ambient>
          <diffuse>0.7 0.7 0.7 1</diffuse>
          <specular>0.01 0.01 0.01 1</specular>
          <emissive>0 0 0 1</emissive>
        </material>
        <transparency>0</transparency>
        <cast_shadows>1</cast_shadows>
      </visual>
    </link>

    <link name='rotor_7'>
      <collision name='rotor_7_collision'>
        <pose>0 0 0 0 -0 0</pose>
        <geometry>
          <cylinder>
            <length>0.015</length>
            <radius>0.4826</radius>
          </cylinder>
        </geometry>
        <surface>
          <contact>
            <ode/>
          </contact>
          <friction>
            <ode/>
          </friction>
        </surface>
      </collision>
      <inertial>
        <mass>0.2</mass>
        <inertia>
          <ixx>0.0194</ixx>
          <ixy>0</ixy>
          <ixz>0</ixz>
          <iyy>0.0194</iyy>
          <iyz>0</iyz>
          <izz>0.0097</izz>
        </inertia>
        <pose>0 0 0 0 -0 0</pose>
      </inertial>
      <pose>1.125441 0.468821 1.08 0.139626 -0.087266 0.398302</pose>
      <gravity>1</gravity>
      <self_collide>0</self_collide>
      <kinematic>0</kinematic>
      <enable_wind>1</enable_wind>
      <visual name='visual'>
        <pose>0 0 0 0 0 0</pose>
        <geometry>
          <mesh>
            <uri>model://Partes/helices_CCW_T30.dae</uri>
            <scale>1 1 1</scale>
          </mesh>
        </geometry>
        <material>
          <lighting>1</lighting>
          <script>
            <uri>file://media/materials/scripts/gazebo.material</uri>
            <name>Gazebo/Grey</name>
          </script>
          <shader type='pixel'>
            <normal_map>__default__</normal_map>
          </shader>
          <ambient>0.3 0.3 0.3 1</ambient>
          <diffuse>0.7 0.7 0.7 1</diffuse>
          <specular>0.01 0.01 0.01 1</specular>
          <emissive>0 0 0 1</emissive>
        </material>
        <transparency>0</transparency>
        <cast_shadows>1</cast_shadows>
      </visual>
    </link>
	<joint name='iris/imu_joint' type='revolute'>
      <child>iris/imu_link</child>
      <parent>base_link</parent>
      <axis>
        <xyz>0 0 1</xyz>
        <limit>
          <lower>0</lower>
          <upper>0</upper>
          <effort>0</effort>
          <velocity>0</velocity>
        </limit>
        <dynamics>
          <damping>1.0</damping>
        </dynamics>
        <use_parent_model_frame>0</use_parent_model_frame>
      </axis>
      <physics>
        <ode>
          <implicit_spring_damper>1</implicit_spring_damper>
        </ode>
      </physics>
    </joint>
	<joint name='rotor_0_joint' type='revolute'>
      <child>rotor_0</child>
      <parent>base_link</parent>
      <axis>
		<xyz>0 0 1</xyz><!-- Eixo ajustado para o roll de 8° e pitch de -5° -->
        <limit>
          <lower>-1e+16</lower>
          <upper>1e+16</upper>
        </limit>
        <dynamics>
          <damping>0.003</damping>
        </dynamics>
        <use_parent_model_frame>0</use_parent_model_frame>
      </axis>
      <physics>
        <ode>
          <implicit_spring_damper>1</implicit_spring_damper>
        </ode>
      </physics>
    </joint>
    <joint name='rotor_1_joint' type='revolute'>
      <child>rotor_1</child>
      <parent>base_link</parent>
      <axis>
		<xyz>0.0 -0.0 1.0</xyz>
        <limit>
          <lower>-1e+16</lower>
          <upper>1e+16</upper>
        </limit>
        <dynamics>
          <damping>0.003</damping>
        </dynamics>
        <use_parent_model_frame>0</use_parent_model_frame>
      </axis>
      <physics>
        <ode>
          <implicit_spring_damper>1</implicit_spring_damper>
        </ode>
      </physics>
    </joint>
    <joint name='rotor_2_joint' type='revolute'>
      <child>rotor_2</child>
      <parent>base_link</parent>
      <axis>
        <xyz>0 0 1</xyz>
        <limit>
          <lower>-1e+16</lower>
          <upper>1e+16</upper>
        </limit>
        <dynamics>
          <damping>0.003</damping>
        </dynamics>
        <use_parent_model_frame>0</use_parent_model_frame>
      </axis>
      <physics>
        <ode>
          <implicit_spring_damper>1</implicit_spring_damper>
        </ode>
      </physics>
    </joint>
    <joint name='rotor_3_joint' type='revolute'>
      <child>rotor_3</child>
      <parent>base_link</parent>
      <axis>
        <xyz>0 0 1</xyz>
        <limit>
          <lower>-1e+16</lower>
          <upper>1e+16</upper>
        </limit>
        <dynamics>
          <damping>0.003</damping>
        </dynamics>
        <use_parent_model_frame>0</use_parent_model_frame>
      </axis>
      <physics>
        <ode>
          <implicit_spring_damper>1</implicit_spring_damper>
        </ode>
      </physics>
    </joint>
    <joint name='rotor_4_joint' type='revolute'>
      <child>rotor_4</child>
      <parent>base_link</parent>
      <axis>
        <xyz>0 0 1</xyz>
        <limit>
          <lower>-1e+16</lower>
          <upper>1e+16</upper>
        </limit>
        <dynamics>
          <damping>0.003</damping>
        </dynamics>
        <use_parent_model_frame>0</use_parent_model_frame>
      </axis>
      <physics>
        <ode>
          <implicit_spring_damper>1</implicit_spring_damper>
        </ode>
      </physics>
    </joint>
    <joint name='rotor_5_joint' type='revolute'>
      <child>rotor_5</child>
      <parent>base_link</parent>
      <axis>
        <xyz>0 0 1</xyz>
        <limit>
          <lower>-1e+16</lower>
          <upper>1e+16</upper>
        </limit>
        <dynamics>
          <damping>0.003</damping>
        </dynamics>
        <use_parent_model_frame>0</use_parent_model_frame>
      </axis>
      <physics>
        <ode>
          <implicit_spring_damper>1</implicit_spring_damper>
        </ode>
      </physics>
    </joint>
    <joint name='rotor_6_joint' type='revolute'>
      <child>rotor_6</child>
      <parent>base_link</parent>
      <axis>
        <xyz>0 0 1</xyz>
        <limit>
          <lower>-1e+16</lower>
          <upper>1e+16</upper>
        </limit>
        <dynamics>
          <damping>0.003</damping>
        </dynamics>
        <use_parent_model_frame>0</use_parent_model_frame>
      </axis>
      <physics>
        <ode>
          <implicit_spring_damper>1</implicit_spring_damper>
        </ode>
      </physics>
    </joint>
    <joint name='rotor_7_joint' type='revolute'>
      <child>rotor_7</child>
      <parent>base_link</parent>
      <axis>
        <xyz>0 0 1</xyz>
        <limit>
          <lower>-1e+16</lower>
          <upper>1e+16</upper>
        </limit>
        <dynamics>
          <damping>0.003</damping>
        </dynamics>
        <use_parent_model_frame>0</use_parent_model_frame>
      </axis>
      <physics>
        <ode>
          <implicit_spring_damper>1</implicit_spring_damper>
        </ode>
      </physics>
    </joint>
	
<!--
    <link name="rotor_0_blade_1_cp">
      <gravity>0</gravity>
      <pose>0.468821 -1.125441 1.08 0.139626 -0.087266 -1.1779</pose>
      <visual name='rotor_0_visual_root'>
        <pose>0 0 0 0 -0 0</pose>
        <geometry>
          <sphere>
            <radius>0.01</radius>
          </sphere>
        </geometry>
      </visual>
      <visual name='rotor_0_visual_tip'>
        <pose>0.4826 0 0 0 -0 0</pose>
        <geometry>
          <sphere>
            <radius>0.01</radius>
          </sphere>
        </geometry>
      </visual>
      <visual name='rotor_0_visual_cp'>
        <pose>0.100 0 0 0 -0 0</pose>
        <geometry>
          <sphere>
            <radius>0.003</radius>
          </sphere>
        </geometry>
      </visual>
      <visual name='rotor_0_visual_cp_forward'>
        <pose>0.100 0.02 0 0 -0 0</pose>
        <geometry>
          <sphere>
            <radius>0.003</radius>
          </sphere>
        </geometry>
      </visual>
      <visual name='rotor_0_visual_cp_upward'>
        <pose>0.100 0 0.02 0 -0 0</pose>
        <geometry>
          <sphere>
            <radius>0.003</radius>
          </sphere>
        </geometry>
      </visual>
    </link>
    <link name="rotor_0_blade_2_cp">
      <gravity>0</gravity>
      <pose>0.468821 -1.125441 1.08 0.139626 -0.087266 -1.1779</pose>
      <visual name='rotor_0_visual_root'>
        <pose>0 0 0 0 -0 0</pose>
        <geometry>
          <sphere>
            <radius>0.01</radius>
          </sphere>
        </geometry>
      </visual>
      <visual name='rotor_0_visual_tip'>
        <pose>-0.4826 0 0 0 -0 0</pose>
        <geometry>
          <sphere>
            <radius>0.01</radius>
          </sphere>
        </geometry>
      </visual>
      <visual name='rotor_0_visual_cp'>
        <pose>-0.100 0 0 0 -0 0</pose>
        <geometry>
          <sphere>
            <radius>0.003</radius>
          </sphere>
        </geometry>
      </visual>
      <visual name='rotor_0_visual_cp_forward'>
        <pose>-0.100 -0.02 0 0 -0 0</pose>
        <geometry>
          <sphere>
            <radius>0.003</radius>
          </sphere>
        </geometry>
      </visual>
      <visual name='rotor_0_visual_cp_upward'>
        <pose>-0.100 0 0.02 0 -0 0</pose>
        <geometry>
          <sphere>
            <radius>0.003</radius>
          </sphere>
        </geometry>
      </visual>
    </link>

    <link name="rotor_1_blade_1_cp">
      <gravity>0</gravity>
      <pose>0.468821 -1.125441 1.08 0.139626 -0.087266 -1.1779</pose>
      <visual name='rotor_1_visual_root'>
        <pose>0 0 0 0 -0 0</pose>
        <geometry>
          <sphere>
            <radius>0.04</radius>
          </sphere>
        </geometry>
      </visual>
      <visual name='rotor_1_visual_tip'>
        <pose>0.4826 0 0 0 -0 0</pose>
        <geometry>
          <sphere>
            <radius>0.02</radius>
          </sphere>
        </geometry>
      </visual>
      <visual name='rotor_1_visual_cp'>
        <pose>0.100 0 0 0 -0 0</pose>
        <geometry>
          <sphere>
            <radius>0.006</radius>
          </sphere>
        </geometry>
      </visual>
      <visual name='rotor_1_visual_cp_forward'>
        <pose>0.100 0.02 0 0 -0 0</pose>
        <geometry>
          <sphere>
            <radius>0.003</radius>
          </sphere>
        </geometry>
		<material>
		  <script>
			<uri>file://media/materials/scripts/gazebo.material</uri>
			<name>Gazebo/Red</name>
		  </script>
		</material>
      </visual>
      <visual name='rotor_1_visual_cp_upward'>
        <pose>0.100 0 0.02 0 -0 0</pose>
        <geometry>
          <sphere>
            <radius>0.003</radius>
          </sphere>
        </geometry>
      </visual>
    </link>
    <link name="rotor_1_blade_2_cp">
      <gravity>0</gravity>
      <pose>0.468821 -1.125441 1.08 0.139626 -0.087266 -1.1779</pose>
      <visual name='rotor_1_visual_root'>
        <pose>0 0 0 0 -0 0</pose>
        <geometry>
          <sphere>
            <radius>0.01</radius>
          </sphere>
        </geometry>
      </visual>
      <visual name='rotor_1_visual_tip'>
        <pose>-0.4826 0 0 0 -0 0</pose>
        <geometry>
          <sphere>
            <radius>0.01</radius>
          </sphere>
        </geometry>
      </visual>
      <visual name='rotor_1_visual_cp'>
        <pose>-0.100 0 0 0 -0 0</pose>
        <geometry>
          <sphere>
            <radius>0.003</radius>
          </sphere>
        </geometry>
      </visual>
      <visual name='rotor_1_visual_cp_forward'>
        <pose>-0.100 -0.02 0 0 -0 0</pose>
        <geometry>
          <sphere>
            <radius>0.003</radius>
          </sphere>
        </geometry>
      </visual>
      <visual name='rotor_1_visual_cp_upward'>
        <pose>-0.100 0 0.02 0 -0 0</pose>
        <geometry>
          <sphere>
            <radius>0.003</radius>
          </sphere>
        </geometry>
      </visual>
    </link>
-->
    <static>0</static>
  </model>
</sdf>